# exception_py_content